2020-10-01 08:31:16 WARNING (MainThread) [homeassistant.loader] You are using a custom integration for sonoff which has not been tested by Home Assistant. This component might cause stability problems, be sure to disable it if you experience issues with Home Assistant.
2020-10-01 08:31:16 WARNING (MainThread) [homeassistant.loader] You are using a custom integration for hacs which has not been tested by Home Assistant. This component might cause stability problems, be sure to disable it if you experience issues with Home Assistant.
2020-10-01 08:31:16 WARNING (MainThread) [homeassistant.loader] You are using a custom integration for apple_tv which has not been tested by Home Assistant. This component might cause stability problems, be sure to disable it if you experience issues with Home Assistant.
2020-10-01 08:31:16 WARNING (MainThread) [homeassistant.loader] You are using a custom integration for spotcast which has not been tested by Home Assistant. This component might cause stability problems, be sure to disable it if you experience issues with Home Assistant.
2020-10-01 08:31:16 WARNING (MainThread) [homeassistant.loader] You are using a custom integration for audiconnect which has not been tested by Home Assistant. This component might cause stability problems, be sure to disable it if you experience issues with Home Assistant.
2020-10-01 08:31:16 WARNING (MainThread) [homeassistant.loader] You are using a custom integration for browser_mod which has not been tested by Home Assistant. This component might cause stability problems, be sure to disable it if you experience issues with Home Assistant.
2020-10-01 08:31:18 WARNING (MainThread) [homeassistant.components.http] The 'base_url' option is deprecated, please remove it from your configuration
2020-10-01 08:31:20 WARNING (MainThread) [homeassistant.components.lovelace] Resources need to be specified in your configuration.yaml. Please see the docs
2020-10-01 08:31:24 ERROR (MainThread) [homeassistant.components.websocket_api.http.connection.140515330945088] Received invalid command: browser_mod/connect
2020-10-01 08:31:38 WARNING (MainThread) [homeassistant.setup] Setup of browser_mod is taking over 10 seconds.
2020-10-01 08:32:26 WARNING (MainThread) [homeassistant.bootstrap] Waiting on integrations to complete setup: browser_mod
2020-10-01 08:32:56 WARNING (MainThread) [slixmpp.stringprep] Using slower stringprep, consider compiling the faster cython/libidn one.
2020-10-01 08:32:57 WARNING (MainThread) [slixmpp.basexmpp] Legacy XMPP 0.9 protocol detected.
2020-10-01 08:32:58 WARNING (MainThread) [slixmpp.basexmpp] Legacy XMPP 0.9 protocol detected.
2020-10-01 08:32:58 WARNING (MainThread) [slixmpp.basexmpp] Legacy XMPP 0.9 protocol detected.
2020-10-01 08:32:59 WARNING (MainThread) [slixmpp.basexmpp] Legacy XMPP 0.9 protocol detected.
2020-10-01 08:33:18 ERROR (MainThread) [homeassistant] Error doing job: Task was destroyed but it is pending!
2020-10-01 08:33:18 ERROR (MainThread) [homeassistant] Error doing job: Task was destroyed but it is pending!
2020-10-01 08:33:18 ERROR (MainThread) [homeassistant] Error doing job: Task was destroyed but it is pending!
2020-10-01 08:33:18 ERROR (MainThread) [homeassistant] Error doing job: Task was destroyed but it is pending!
2020-10-01 08:33:20 WARNING (MainThread) [homeassistant.components.template.sensor] The 'entity_id' option is deprecated, please remove it from your configuration
2020-10-01 08:33:20 WARNING (MainThread) [homeassistant.components.template.sensor] The 'entity_id' option is deprecated, please remove it from your configuration
2020-10-01 08:33:20 WARNING (MainThread) [homeassistant.loader] You are using a custom integration for google_geocode which has not been tested by Home Assistant. This component might cause stability problems, be sure to disable it if you experience issues with Home Assistant.
2020-10-01 08:33:20 WARNING (MainThread) [homeassistant.loader] You are using a custom integration for plex_recently_added which has not been tested by Home Assistant. This component might cause stability problems, be sure to disable it if you experience issues with Home Assistant.
2020-10-01 08:33:26 WARNING (MainThread) [homeassistant.bootstrap] Waiting on integrations to complete setup: browser_mod
2020-10-01 08:33:54 WARNING (MainThread) [homeassistant.components.media_player] MediaPlayerDevice is deprecated, modify AppleTvDevice to extend MediaPlayerEntity
2020-10-01 08:33:54 WARNING (MainThread) [homeassistant.components.remote] RemoteDevice is deprecated, modify AppleTVRemote to extend RemoteEntity
2020-10-01 08:33:54 ERROR (MainThread) [homeassistant.components.sensor] Platform xiaomi_aqara does not generate unique IDs. ID Battery158d0002b83d41 already exists - ignoring sensor.battery_158d0002b83d41
2020-10-01 08:34:03 ERROR (MainThread) [homeassistant.helpers.event] Error while processing template: Template("{{ states.input_number.alarm_clock_hour.state | int }}")
Traceback (most recent call last):
  File "/usr/src/homeassistant/homeassistant/helpers/template.py", line 285, in async_render
    return compiled.render(kwargs).strip()
  File "/usr/local/lib/python3.8/site-packages/jinja2/environment.py", line 1090, in render
    self.environment.handle_exception()
  File "/usr/local/lib/python3.8/site-packages/jinja2/environment.py", line 832, in handle_exception
    reraise(*rewrite_traceback_stack(source=source))
  File "/usr/local/lib/python3.8/site-packages/jinja2/_compat.py", line 28, in reraise
    raise value.with_traceback(tb)
  File "<template>", line 1, in top-level template code
  File "/usr/local/lib/python3.8/site-packages/jinja2/filters.py", line 779, in do_int
    return int(value)
jinja2.exceptions.UndefinedError: 'None' has no attribute 'state'

The above exception was the direct cause of the following exception:

Traceback (most recent call last):
  File "/usr/src/homeassistant/homeassistant/helpers/template.py", line 306, in async_render_to_info
    render_info._result = self.async_render(variables, **kwargs)
  File "/usr/src/homeassistant/homeassistant/helpers/template.py", line 287, in async_render
    raise TemplateError(err) from err
homeassistant.exceptions.TemplateError: UndefinedError: 'None' has no attribute 'state'
2020-10-01 08:34:03 ERROR (MainThread) [homeassistant.components.template.template_entity] TemplateError('UndefinedError: 'None' has no attribute 'state'') while processing template 'Template("{{ states.input_number.alarm_clock_hour.state | int }}")' for attribute '_state' in entity 'sensor.alarm_clock_hour'
2020-10-01 08:34:03 ERROR (MainThread) [homeassistant.helpers.event] Error while processing template: Template("{{ states.input_number.alarm_clock_minute.state | int }}")
Traceback (most recent call last):
  File "/usr/src/homeassistant/homeassistant/helpers/template.py", line 285, in async_render
    return compiled.render(kwargs).strip()
  File "/usr/local/lib/python3.8/site-packages/jinja2/environment.py", line 1090, in render
    self.environment.handle_exception()
  File "/usr/local/lib/python3.8/site-packages/jinja2/environment.py", line 832, in handle_exception
    reraise(*rewrite_traceback_stack(source=source))
  File "/usr/local/lib/python3.8/site-packages/jinja2/_compat.py", line 28, in reraise
    raise value.with_traceback(tb)
  File "<template>", line 1, in top-level template code
  File "/usr/local/lib/python3.8/site-packages/jinja2/filters.py", line 779, in do_int
    return int(value)
jinja2.exceptions.UndefinedError: 'None' has no attribute 'state'

The above exception was the direct cause of the following exception:

Traceback (most recent call last):
  File "/usr/src/homeassistant/homeassistant/helpers/template.py", line 306, in async_render_to_info
    render_info._result = self.async_render(variables, **kwargs)
  File "/usr/src/homeassistant/homeassistant/helpers/template.py", line 287, in async_render
    raise TemplateError(err) from err
homeassistant.exceptions.TemplateError: UndefinedError: 'None' has no attribute 'state'
2020-10-01 08:34:03 ERROR (MainThread) [homeassistant.components.template.template_entity] TemplateError('UndefinedError: 'None' has no attribute 'state'') while processing template 'Template("{{ states.input_number.alarm_clock_minute.state | int }}")' for attribute '_state' in entity 'sensor.alarm_clock_minute'
2020-10-01 08:37:28 WARNING (zeroconf-Engine-304) [zeroconf] Error sending through socket 38
Traceback (most recent call last):
  File "/usr/local/lib/python3.8/site-packages/zeroconf/__init__.py", line 2889, in send
    bytes_sent = s.sendto(packet, 0, (real_addr, port))
OSError: [Errno 101] Network unreachable
2020-10-01 08:48:37 ERROR (MainThread) [frontend.js.latest.202009182] https://casatinus.duckdns.org/local/community/custom-header/custom-header.js:1:4632 Uncaught TypeError: Cannot read property 'hass' of null
2020-10-01 09:24:05 WARNING (MainThread) [homeassistant.helpers.entity] Update of binary_sensor.slaapkamer_raam is taking over 10 seconds
2020-10-01 09:24:05 ERROR (SyncWorker_23) [xiaomi_gateway] Cannot connect to Gateway
2020-10-01 09:24:05 ERROR (SyncWorker_23) [xiaomi_gateway] No data in response from hub None
2020-10-01 10:54:02 WARNING (MainThread) [homeassistant.helpers.service] Unable to find referenced entities light.slaapkamer_spot
2020-10-01 11:08:51 ERROR (MainThread) [homeassistant] Error doing job: Task was destroyed but it is pending!
2020-10-01 11:08:51 ERROR (MainThread) [homeassistant] Error doing job: Task was destroyed but it is pending!
2020-10-01 11:33:05 WARNING (MainThread) [homeassistant.helpers.entity] Update of binary_sensor.kantoor_deur is taking over 10 seconds
2020-10-01 11:33:05 ERROR (SyncWorker_11) [xiaomi_gateway] Cannot connect to Gateway
2020-10-01 11:33:05 ERROR (SyncWorker_11) [xiaomi_gateway] No data in response from hub None
2020-10-01 12:03:57 WARNING (MainThread) [homeassistant.helpers.service] Unable to find referenced entities light.slaapkamer_spot
2020-10-01 12:18:52 WARNING (MainThread) [homeassistant.helpers.service] Unable to find referenced entities light.slaapkamer_spot
2020-10-01 12:28:52 WARNING (MainThread) [homeassistant.helpers.service] Unable to find referenced entities light.slaapkamer_spot
2020-10-01 12:59:05 WARNING (MainThread) [homeassistant.helpers.entity] Update of binary_sensor.badkamer_deur is taking over 10 seconds
2020-10-01 12:59:05 ERROR (SyncWorker_17) [xiaomi_gateway] Cannot connect to Gateway
2020-10-01 12:59:05 ERROR (SyncWorker_17) [xiaomi_gateway] No data in response from hub None
2020-10-01 13:37:05 WARNING (MainThread) [homeassistant.helpers.entity] Update of binary_sensor.badkamer_deur is taking over 10 seconds
2020-10-01 13:37:05 ERROR (SyncWorker_41) [xiaomi_gateway] Cannot connect to Gateway
2020-10-01 13:37:05 ERROR (SyncWorker_41) [xiaomi_gateway] No data in response from hub None
2020-10-01 13:43:15 ERROR (MainThread) [custom_components.audiconnect.audi_connect_account] Unable to obtain the vehicle status report of WAUZZZF48GA044048: 504, message='Gateway Timeout', url=URL('https://msg.volkswagen.de/fs-car/bs/vsr/v1/Audi/DE/vehicles/WAUZZZF48GA044048/status')
2020-10-01 17:31:29 WARNING (Thread-16) [pychromecast.socket_client] [Zolder(10.0.1.218):8009] Heartbeat timeout, resetting connection
2020-10-01 17:31:59 ERROR (Thread-16) [pychromecast.socket_client] [Zolder(10.0.1.218):8009] Failed to connect to service Google-Home-Mini-5a8ad85bff565eccaca50dde01d25ccc._googlecast._tcp.local., retrying in 5.0s
2020-10-01 17:44:44 WARNING (Thread-16) [pychromecast.socket_client] [Zolder(10.0.1.218):8009] Heartbeat timeout, resetting connection
2020-10-01 17:45:14 ERROR (Thread-16) [pychromecast.socket_client] [Zolder(10.0.1.218):8009] Failed to connect to service Google-Home-Mini-5a8ad85bff565eccaca50dde01d25ccc._googlecast._tcp.local., retrying in 5.0s
2020-10-01 18:28:55 WARNING (zeroconf-ServiceBrowser__googlecast._tcp.local._369) [homeassistant.components.cast.discovery] setup_internal_discovery failed to get info for c2e35834-c0ca-4ea8-94b8-e2cb9d3d494e, Google-Cast-Group-C2E35834C0CA4EA894B8E2CB9D3D494E._googlecast._tcp.local.
2020-10-01 18:50:06 WARNING (MainThread) [homeassistant.helpers.entity] Update of binary_sensor.badkamer_deur is taking over 10 seconds
2020-10-01 18:50:06 ERROR (SyncWorker_29) [xiaomi_gateway] Cannot connect to Gateway
2020-10-01 18:50:06 ERROR (SyncWorker_29) [xiaomi_gateway] No data in response from hub None
2020-10-01 19:20:53 WARNING (MainThread) [homeassistant.components.light.reproduce_state] The use of other attributes than device state attributes is deprecated and will be removed in a future release. Invalid attributes are ['transition', 'brightness_pct']. Read the logs for further details: https://www.home-assistant.io/integrations/scene/
2020-10-01 20:45:42 ERROR (SyncWorker_47) [homeassistant.components.qnap.sensor] Failed to fetch QNAP stats from the NAS
Traceback (most recent call last):
  File "/usr/local/lib/python3.8/site-packages/urllib3/connectionpool.py", line 426, in _make_request
    six.raise_from(e, None)
  File "<string>", line 3, in raise_from
  File "/usr/local/lib/python3.8/site-packages/urllib3/connectionpool.py", line 421, in _make_request
    httplib_response = conn.getresponse()
  File "/usr/local/lib/python3.8/http/client.py", line 1347, in getresponse
    response.begin()
  File "/usr/local/lib/python3.8/http/client.py", line 307, in begin
    version, status, reason = self._read_status()
  File "/usr/local/lib/python3.8/http/client.py", line 268, in _read_status
    line = str(self.fp.readline(_MAXLINE + 1), "iso-8859-1")
  File "/usr/local/lib/python3.8/socket.py", line 669, in readinto
    return self._sock.recv_into(b)
socket.timeout: timed out

During handling of the above exception, another exception occurred:

Traceback (most recent call last):
  File "/usr/local/lib/python3.8/site-packages/requests/adapters.py", line 439, in send
    resp = conn.urlopen(
  File "/usr/local/lib/python3.8/site-packages/urllib3/connectionpool.py", line 726, in urlopen
    retries = retries.increment(
  File "/usr/local/lib/python3.8/site-packages/urllib3/util/retry.py", line 403, in increment
    raise six.reraise(type(error), error, _stacktrace)
  File "/usr/local/lib/python3.8/site-packages/urllib3/packages/six.py", line 735, in reraise
    raise value
  File "/usr/local/lib/python3.8/site-packages/urllib3/connectionpool.py", line 670, in urlopen
    httplib_response = self._make_request(
  File "/usr/local/lib/python3.8/site-packages/urllib3/connectionpool.py", line 428, in _make_request
    self._raise_timeout(err=e, url=url, timeout_value=read_timeout)
  File "/usr/local/lib/python3.8/site-packages/urllib3/connectionpool.py", line 335, in _raise_timeout
    raise ReadTimeoutError(
urllib3.exceptions.ReadTimeoutError: HTTPConnectionPool(host='10.0.1.101', port=8080): Read timed out. (read timeout=5)

During handling of the above exception, another exception occurred:

Traceback (most recent call last):
  File "/usr/src/homeassistant/homeassistant/components/qnap/sensor.py", line 195, in update
    self.data["system_health"] = self._api.get_system_health()
  File "/usr/local/lib/python3.8/site-packages/qnapstats/qnap_stats.py", line 121, in get_system_health
    resp = self._get_url("management/manaRequest.cgi?subfunc=sysinfo&sysHealth=1")
  File "/usr/local/lib/python3.8/site-packages/qnapstats/qnap_stats.py", line 69, in _get_url
    result = self._execute_get_url(url, **kwargs)
  File "/usr/local/lib/python3.8/site-packages/qnapstats/qnap_stats.py", line 85, in _execute_get_url
    resp = self._session.get(url, timeout=self._timeout, verify=self._verify_ssl)
  File "/usr/local/lib/python3.8/site-packages/requests/sessions.py", line 543, in get
    return self.request('GET', url, **kwargs)
  File "/usr/local/lib/python3.8/site-packages/requests/sessions.py", line 530, in request
    resp = self.send(prep, **send_kwargs)
  File "/usr/local/lib/python3.8/site-packages/requests/sessions.py", line 643, in send
    r = adapter.send(request, **kwargs)
  File "/usr/local/lib/python3.8/site-packages/requests/adapters.py", line 529, in send
    raise ReadTimeout(e, request=request)
requests.exceptions.ReadTimeout: HTTPConnectionPool(host='10.0.1.101', port=8080): Read timed out. (read timeout=5)
2020-10-01 21:18:05 ERROR (MainThread) [aioharmony.hubconnector_xmpp] 10.0.1.165: Connecting to HUB failed with error: [Errno 111] Connect call failed ('10.0.1.165', 5222)
2020-10-01 21:18:07 ERROR (MainThread) [aioharmony.hubconnector_xmpp] 10.0.1.165: Connecting to HUB failed with error: [Errno 111] Connect call failed ('10.0.1.165', 5222)
2020-10-01 21:25:22 ERROR (MainThread) [homeassistant] Error doing job: Task was destroyed but it is pending!
2020-10-01 21:25:22 ERROR (MainThread) [homeassistant] Error doing job: Task was destroyed but it is pending!
2020-10-01 22:06:22 ERROR (MainThread) [homeassistant.components.websocket_api.http.connection.140514987283216] Client unable to keep up with pending messages. Stayed over 512 for 5 seconds
2020-10-02 01:37:08 WARNING (MainThread) [homeassistant.helpers.entity] Update of binary_sensor.badkamer_deur is taking over 10 seconds
2020-10-02 01:37:08 ERROR (SyncWorker_39) [xiaomi_gateway] Cannot connect to Gateway
2020-10-02 01:37:08 ERROR (SyncWorker_39) [xiaomi_gateway] No data in response from hub None
2020-10-02 02:00:38 WARNING (MainThread) [homeassistant.helpers.entity] Update of binary_sensor.badkamer_deur is taking over 10 seconds
2020-10-02 02:00:38 ERROR (SyncWorker_59) [xiaomi_gateway] Cannot connect to Gateway
2020-10-02 02:00:38 ERROR (SyncWorker_59) [xiaomi_gateway] No data in response from hub None
2020-10-02 02:02:09 WARNING (MainThread) [homeassistant.helpers.entity] Update of binary_sensor.slaapkamer_raam is taking over 10 seconds
2020-10-02 02:02:09 ERROR (SyncWorker_62) [xiaomi_gateway] Cannot connect to Gateway
2020-10-02 02:02:09 ERROR (SyncWorker_62) [xiaomi_gateway] No data in response from hub None
2020-10-02 02:06:16 WARNING (Thread-10) [pychromecast.socket_client] [Logeerkamer Google Home(10.0.1.124):8009] Heartbeat timeout, resetting connection
2020-10-02 02:42:13 ERROR (Thread-14) [pychromecast.socket_client] [huis(10.0.1.193):32205] Error reading from socket.
2020-10-02 02:42:13 WARNING (Thread-14) [pychromecast.socket_client] [huis(10.0.1.193):32205] Error communicating with socket, resetting connection
2020-10-02 02:42:38 WARNING (Thread-13) [pychromecast.socket_client] [Google Home Woonkamer(10.0.1.193):8009] Heartbeat timeout, resetting connection
2020-10-02 02:43:08 ERROR (Thread-14) [pychromecast.socket_client] [huis(10.0.1.221):42893] Error reading from socket.
2020-10-02 02:43:08 WARNING (Thread-14) [pychromecast.socket_client] [huis(10.0.1.221):42893] Error communicating with socket, resetting connection
2020-10-02 02:43:20 WARNING (zeroconf-ServiceBrowser__googlecast._tcp.local._369) [homeassistant.components.cast.discovery] setup_internal_discovery failed to get info for c2e35834-c0ca-4ea8-94b8-e2cb9d3d494e, Google-Cast-Group-C2E35834C0CA4EA894B8E2CB9D3D494E._googlecast._tcp.local.
2020-10-02 02:45:09 WARNING (MainThread) [homeassistant.helpers.entity] Update of binary_sensor.badkamer_deur is taking over 10 seconds
2020-10-02 02:45:09 ERROR (SyncWorker_35) [xiaomi_gateway] Cannot connect to Gateway
2020-10-02 02:45:09 ERROR (SyncWorker_35) [xiaomi_gateway] No data in response from hub None
2020-10-02 03:00:39 WARNING (MainThread) [homeassistant.helpers.entity] Update of binary_sensor.slaapkamer_raam is taking over 10 seconds
2020-10-02 03:00:39 ERROR (SyncWorker_38) [xiaomi_gateway] Cannot connect to Gateway
2020-10-02 03:00:39 ERROR (SyncWorker_38) [xiaomi_gateway] No data in response from hub None
2020-10-02 03:04:02 ERROR (MainThread) [homeassistant] Error doing job: Task was destroyed but it is pending!
2020-10-02 03:08:09 WARNING (MainThread) [homeassistant.helpers.entity] Update of binary_sensor.badkamer_deur is taking over 10 seconds
2020-10-02 03:08:09 ERROR (SyncWorker_39) [xiaomi_gateway] Cannot connect to Gateway
2020-10-02 03:08:09 ERROR (SyncWorker_39) [xiaomi_gateway] No data in response from hub None
2020-10-02 03:11:19 WARNING (Thread-11) [pychromecast.socket_client] [Slaapkamer Cast(10.0.1.219):8009] Heartbeat timeout, resetting connection
2020-10-02 03:12:20 WARNING (Thread-15) [pychromecast.socket_client] [Kantoor hub(10.0.1.206):8009] Heartbeat timeout, resetting connection
2020-10-02 03:46:39 WARNING (MainThread) [homeassistant.helpers.entity] Update of binary_sensor.badkamer_deur is taking over 10 seconds
2020-10-02 03:46:39 ERROR (SyncWorker_39) [xiaomi_gateway] Cannot connect to Gateway
2020-10-02 03:46:39 ERROR (SyncWorker_39) [xiaomi_gateway] No data in response from hub None
2020-10-02 04:27:35 WARNING (Thread-16) [pychromecast.socket_client] [Zolder(10.0.1.218):8009] Heartbeat timeout, resetting connection
2020-10-02 04:39:52 WARNING (Thread-12) [pychromecast.socket_client] [Slaapkamer Hub(10.0.1.221):8009] Heartbeat timeout, resetting connection
2020-10-02 05:37:09 WARNING (MainThread) [homeassistant.helpers.entity] Update of binary_sensor.logeerkamer_raam is taking over 10 seconds
2020-10-02 05:37:09 ERROR (SyncWorker_22) [xiaomi_gateway] Cannot connect to Gateway
2020-10-02 05:37:09 ERROR (SyncWorker_22) [xiaomi_gateway] No data in response from hub None
2020-10-02 05:58:09 WARNING (MainThread) [homeassistant.helpers.entity] Update of binary_sensor.badkamer_deur is taking over 10 seconds
2020-10-02 05:58:09 ERROR (SyncWorker_12) [xiaomi_gateway] Cannot connect to Gateway
2020-10-02 05:58:09 ERROR (SyncWorker_12) [xiaomi_gateway] No data in response from hub None
2020-10-02 06:09:44 ERROR (SyncWorker_43) [homeassistant.components.qnap.sensor] Failed to fetch QNAP stats from the NAS
Traceback (most recent call last):
  File "/usr/local/lib/python3.8/site-packages/urllib3/connectionpool.py", line 426, in _make_request
    six.raise_from(e, None)
  File "<string>", line 3, in raise_from
  File "/usr/local/lib/python3.8/site-packages/urllib3/connectionpool.py", line 421, in _make_request
    httplib_response = conn.getresponse()
  File "/usr/local/lib/python3.8/http/client.py", line 1347, in getresponse
    response.begin()
  File "/usr/local/lib/python3.8/http/client.py", line 307, in begin
    version, status, reason = self._read_status()
  File "/usr/local/lib/python3.8/http/client.py", line 268, in _read_status
    line = str(self.fp.readline(_MAXLINE + 1), "iso-8859-1")
  File "/usr/local/lib/python3.8/socket.py", line 669, in readinto
    return self._sock.recv_into(b)
socket.timeout: timed out

During handling of the above exception, another exception occurred:

Traceback (most recent call last):
  File "/usr/local/lib/python3.8/site-packages/requests/adapters.py", line 439, in send
    resp = conn.urlopen(
  File "/usr/local/lib/python3.8/site-packages/urllib3/connectionpool.py", line 726, in urlopen
    retries = retries.increment(
  File "/usr/local/lib/python3.8/site-packages/urllib3/util/retry.py", line 403, in increment
    raise six.reraise(type(error), error, _stacktrace)
  File "/usr/local/lib/python3.8/site-packages/urllib3/packages/six.py", line 735, in reraise
    raise value
  File "/usr/local/lib/python3.8/site-packages/urllib3/connectionpool.py", line 670, in urlopen
    httplib_response = self._make_request(
  File "/usr/local/lib/python3.8/site-packages/urllib3/connectionpool.py", line 428, in _make_request
    self._raise_timeout(err=e, url=url, timeout_value=read_timeout)
  File "/usr/local/lib/python3.8/site-packages/urllib3/connectionpool.py", line 335, in _raise_timeout
    raise ReadTimeoutError(
urllib3.exceptions.ReadTimeoutError: HTTPConnectionPool(host='10.0.1.101', port=8080): Read timed out. (read timeout=5)

During handling of the above exception, another exception occurred:

Traceback (most recent call last):
  File "/usr/src/homeassistant/homeassistant/components/qnap/sensor.py", line 195, in update
    self.data["system_health"] = self._api.get_system_health()
  File "/usr/local/lib/python3.8/site-packages/qnapstats/qnap_stats.py", line 121, in get_system_health
    resp = self._get_url("management/manaRequest.cgi?subfunc=sysinfo&sysHealth=1")
  File "/usr/local/lib/python3.8/site-packages/qnapstats/qnap_stats.py", line 69, in _get_url
    result = self._execute_get_url(url, **kwargs)
  File "/usr/local/lib/python3.8/site-packages/qnapstats/qnap_stats.py", line 85, in _execute_get_url
    resp = self._session.get(url, timeout=self._timeout, verify=self._verify_ssl)
  File "/usr/local/lib/python3.8/site-packages/requests/sessions.py", line 543, in get
    return self.request('GET', url, **kwargs)
  File "/usr/local/lib/python3.8/site-packages/requests/sessions.py", line 530, in request
    resp = self.send(prep, **send_kwargs)
  File "/usr/local/lib/python3.8/site-packages/requests/sessions.py", line 643, in send
    r = adapter.send(request, **kwargs)
  File "/usr/local/lib/python3.8/site-packages/requests/adapters.py", line 529, in send
    raise ReadTimeout(e, request=request)
requests.exceptions.ReadTimeout: HTTPConnectionPool(host='10.0.1.101', port=8080): Read timed out. (read timeout=5)
2020-10-02 06:24:09 WARNING (MainThread) [homeassistant.helpers.entity] Update of binary_sensor.slaapkamer_raam is taking over 10 seconds
2020-10-02 06:24:09 ERROR (SyncWorker_61) [xiaomi_gateway] Cannot connect to Gateway
2020-10-02 06:24:09 ERROR (SyncWorker_61) [xiaomi_gateway] No data in response from hub None
2020-10-02 07:00:39 WARNING (MainThread) [homeassistant.helpers.entity] Update of binary_sensor.slaapkamer_raam is taking over 10 seconds
2020-10-02 07:00:39 ERROR (SyncWorker_63) [xiaomi_gateway] Cannot connect to Gateway
2020-10-02 07:00:39 ERROR (SyncWorker_63) [xiaomi_gateway] No data in response from hub None
2020-10-02 07:37:10 ERROR (SyncWorker_43) [xiaomi_gateway] Cannot connect to Gateway
2020-10-02 07:37:10 ERROR (SyncWorker_43) [xiaomi_gateway] No data in response from hub None
2020-10-02 07:37:10 WARNING (MainThread) [homeassistant.helpers.entity] Update of binary_sensor.logeerkamer_raam is taking over 10 seconds
2020-10-02 08:05:25 WARNING (MainThread) [homeassistant.components.media_player] Updating squeezebox media_player took longer than the scheduled update interval 0:00:10
2020-10-02 08:05:25 WARNING (MainThread) [homeassistant.helpers.entity] Update of media_player.office_squeezebox is taking over 10 seconds
2020-10-02 08:05:25 ERROR (MainThread) [pysqueezebox.server] Failed communicating with LMS: <class 'asyncio.exceptions.TimeoutError'>
2020-10-02 08:05:25 WARNING (MainThread) [homeassistant.helpers.entity] Update of media_player.guest_room_squeezebox is taking over 10 seconds
2020-10-02 08:05:25 ERROR (MainThread) [pysqueezebox.server] Failed communicating with LMS: <class 'asyncio.exceptions.TimeoutError'>
2020-10-02 08:05:25 WARNING (MainThread) [homeassistant.helpers.entity] Update of media_player.batcave is taking over 10 seconds
2020-10-02 08:05:25 WARNING (MainThread) [homeassistant.helpers.entity] Update of media_player.living_room_squeezebox is taking over 10 seconds
2020-10-02 08:05:25 ERROR (MainThread) [pysqueezebox.server] Failed communicating with LMS: <class 'asyncio.exceptions.TimeoutError'>
2020-10-02 08:05:25 ERROR (MainThread) [pysqueezebox.server] Failed communicating with LMS: <class 'asyncio.exceptions.TimeoutError'>
2020-10-02 08:05:45 WARNING (MainThread) [homeassistant.helpers.entity] Update of media_player.office_squeezebox is taking over 10 seconds
2020-10-02 08:05:45 WARNING (MainThread) [homeassistant.components.media_player] Updating squeezebox media_player took longer than the scheduled update interval 0:00:10
2020-10-02 08:05:45 ERROR (MainThread) [pysqueezebox.server] Failed communicating with LMS: <class 'asyncio.exceptions.TimeoutError'>
2020-10-02 08:05:45 WARNING (MainThread) [homeassistant.helpers.entity] Update of media_player.guest_room_squeezebox is taking over 10 seconds
2020-10-02 08:05:45 ERROR (MainThread) [pysqueezebox.server] Failed communicating with LMS: <class 'asyncio.exceptions.TimeoutError'>
2020-10-02 08:05:45 WARNING (MainThread) [homeassistant.helpers.entity] Update of media_player.batcave is taking over 10 seconds
2020-10-02 08:05:45 ERROR (MainThread) [pysqueezebox.server] Failed communicating with LMS: <class 'asyncio.exceptions.TimeoutError'>
2020-10-02 08:05:45 WARNING (MainThread) [homeassistant.helpers.entity] Update of media_player.living_room_squeezebox is taking over 10 seconds
2020-10-02 08:05:45 ERROR (MainThread) [pysqueezebox.server] Failed communicating with LMS: <class 'asyncio.exceptions.TimeoutError'>
2020-10-02 08:06:05 WARNING (MainThread) [homeassistant.helpers.entity] Update of media_player.office_squeezebox is taking over 10 seconds
2020-10-02 08:06:05 WARNING (MainThread) [homeassistant.components.media_player] Updating squeezebox media_player took longer than the scheduled update interval 0:00:10
2020-10-02 08:06:05 ERROR (MainThread) [pysqueezebox.server] Failed communicating with LMS: <class 'asyncio.exceptions.TimeoutError'>
2020-10-02 08:06:05 WARNING (MainThread) [homeassistant.helpers.entity] Update of media_player.guest_room_squeezebox is taking over 10 seconds
2020-10-02 08:06:05 WARNING (MainThread) [homeassistant.helpers.entity] Update of media_player.batcave is taking over 10 seconds
2020-10-02 08:06:05 ERROR (MainThread) [pysqueezebox.server] Failed communicating with LMS: <class 'asyncio.exceptions.TimeoutError'>
2020-10-02 08:06:05 ERROR (MainThread) [pysqueezebox.server] Failed communicating with LMS: <class 'asyncio.exceptions.TimeoutError'>
2020-10-02 08:06:05 WARNING (MainThread) [homeassistant.helpers.entity] Update of media_player.living_room_squeezebox is taking over 10 seconds
2020-10-02 08:06:05 ERROR (MainThread) [pysqueezebox.server] Failed communicating with LMS: <class 'asyncio.exceptions.TimeoutError'>
2020-10-02 08:06:06 ERROR (MainThread) [pysqueezebox.server] Failed communicating with LMS: <class 'asyncio.exceptions.TimeoutError'>
2020-10-02 08:59:47 WARNING (MainThread) [homeassistant.helpers.service] Unable to find referenced entities light.slaapkamer_spot
2020-10-02 09:03:18 WARNING (MainThread) [homeassistant.components.websocket_api.http.connection.140514855200416] Disconnected: Did not receive auth message within 10 seconds
2020-10-02 10:24:11 WARNING (MainThread) [homeassistant.helpers.entity] Update of binary_sensor.badkamer_deur is taking over 10 seconds
2020-10-02 10:24:11 ERROR (SyncWorker_12) [xiaomi_gateway] Cannot connect to Gateway
2020-10-02 10:24:11 ERROR (SyncWorker_12) [xiaomi_gateway] No data in response from hub None
2020-10-02 11:37:12 ERROR (SyncWorker_54) [xiaomi_gateway] Cannot connect to Gateway
2020-10-02 11:37:12 WARNING (MainThread) [homeassistant.helpers.entity] Update of binary_sensor.slaapkamer_deur is taking over 10 seconds
2020-10-02 11:37:12 ERROR (SyncWorker_54) [xiaomi_gateway] No data in response from hub None
2020-10-02 11:38:41 WARNING (MainThread) [homeassistant.helpers.entity] Update of binary_sensor.badkamer_deur is taking over 10 seconds
2020-10-02 11:38:41 ERROR (SyncWorker_40) [xiaomi_gateway] Cannot connect to Gateway
2020-10-02 11:38:41 ERROR (SyncWorker_40) [xiaomi_gateway] No data in response from hub None
2020-10-02 12:24:11 WARNING (MainThread) [homeassistant.helpers.entity] Update of binary_sensor.slaapkamer_deur is taking over 10 seconds
2020-10-02 12:24:11 ERROR (SyncWorker_21) [xiaomi_gateway] Cannot connect to Gateway
2020-10-02 12:24:11 ERROR (SyncWorker_21) [xiaomi_gateway] No data in response from hub None
2020-10-02 12:37:11 WARNING (MainThread) [homeassistant.helpers.entity] Update of binary_sensor.logeerkamer_raam is taking over 10 seconds
2020-10-02 12:37:11 ERROR (SyncWorker_19) [xiaomi_gateway] Cannot connect to Gateway
2020-10-02 12:37:11 ERROR (SyncWorker_19) [xiaomi_gateway] No data in response from hub None
2020-10-02 13:03:45 ERROR (SyncWorker_53) [homeassistant.components.qnap.sensor] Failed to fetch QNAP stats from the NAS
Traceback (most recent call last):
  File "/usr/local/lib/python3.8/site-packages/urllib3/connectionpool.py", line 426, in _make_request
    six.raise_from(e, None)
  File "<string>", line 3, in raise_from
  File "/usr/local/lib/python3.8/site-packages/urllib3/connectionpool.py", line 421, in _make_request
    httplib_response = conn.getresponse()
  File "/usr/local/lib/python3.8/http/client.py", line 1347, in getresponse
    response.begin()
  File "/usr/local/lib/python3.8/http/client.py", line 307, in begin
    version, status, reason = self._read_status()
  File "/usr/local/lib/python3.8/http/client.py", line 268, in _read_status
    line = str(self.fp.readline(_MAXLINE + 1), "iso-8859-1")
  File "/usr/local/lib/python3.8/socket.py", line 669, in readinto
    return self._sock.recv_into(b)
socket.timeout: timed out

During handling of the above exception, another exception occurred:

Traceback (most recent call last):
  File "/usr/local/lib/python3.8/site-packages/requests/adapters.py", line 439, in send
    resp = conn.urlopen(
  File "/usr/local/lib/python3.8/site-packages/urllib3/connectionpool.py", line 726, in urlopen
    retries = retries.increment(
  File "/usr/local/lib/python3.8/site-packages/urllib3/util/retry.py", line 403, in increment
    raise six.reraise(type(error), error, _stacktrace)
  File "/usr/local/lib/python3.8/site-packages/urllib3/packages/six.py", line 735, in reraise
    raise value
  File "/usr/local/lib/python3.8/site-packages/urllib3/connectionpool.py", line 670, in urlopen
    httplib_response = self._make_request(
  File "/usr/local/lib/python3.8/site-packages/urllib3/connectionpool.py", line 428, in _make_request
    self._raise_timeout(err=e, url=url, timeout_value=read_timeout)
  File "/usr/local/lib/python3.8/site-packages/urllib3/connectionpool.py", line 335, in _raise_timeout
    raise ReadTimeoutError(
urllib3.exceptions.ReadTimeoutError: HTTPConnectionPool(host='10.0.1.101', port=8080): Read timed out. (read timeout=5)

During handling of the above exception, another exception occurred:

Traceback (most recent call last):
  File "/usr/src/homeassistant/homeassistant/components/qnap/sensor.py", line 195, in update
    self.data["system_health"] = self._api.get_system_health()
  File "/usr/local/lib/python3.8/site-packages/qnapstats/qnap_stats.py", line 121, in get_system_health
    resp = self._get_url("management/manaRequest.cgi?subfunc=sysinfo&sysHealth=1")
  File "/usr/local/lib/python3.8/site-packages/qnapstats/qnap_stats.py", line 69, in _get_url
    result = self._execute_get_url(url, **kwargs)
  File "/usr/local/lib/python3.8/site-packages/qnapstats/qnap_stats.py", line 85, in _execute_get_url
    resp = self._session.get(url, timeout=self._timeout, verify=self._verify_ssl)
  File "/usr/local/lib/python3.8/site-packages/requests/sessions.py", line 543, in get
    return self.request('GET', url, **kwargs)
  File "/usr/local/lib/python3.8/site-packages/requests/sessions.py", line 530, in request
    resp = self.send(prep, **send_kwargs)
  File "/usr/local/lib/python3.8/site-packages/requests/sessions.py", line 643, in send
    r = adapter.send(request, **kwargs)
  File "/usr/local/lib/python3.8/site-packages/requests/adapters.py", line 529, in send
    raise ReadTimeout(e, request=request)
requests.exceptions.ReadTimeout: HTTPConnectionPool(host='10.0.1.101', port=8080): Read timed out. (read timeout=5)
2020-10-02 16:11:39 ERROR (MainThread) [custom_components.audiconnect.audi_connect_account] Unable to update the vehicle position of WAUZZZF48GA044048: 204, message='No Content', url=URL('https://msg.volkswagen.de/fs-car/bs/cf/v1/Audi/DE/vehicles/WAUZZZF48GA044048/position')
2020-10-02 16:24:37 ERROR (MainThread) [homeassistant.components.websocket_api.http.connection.140514626358048] Client unable to keep up with pending messages. Stayed over 512 for 5 seconds
